<?xml version="1.0" ?>
<robot name="agv" xmlns:xacro="http://www.ros.org/wiki/xacro">

<xacro:include filename="$(find agv_description)/urdf/materials.xacro" />
<xacro:include filename="$(find agv_description)/urdf/agv.trans" />
<xacro:include filename="$(find agv_description)/urdf/agv.gazebo" />
<link name="base_link">
  <inertial>
    <origin xyz="0.0016258729395881844 -3.191490012182206e-17 0.13430005189529884" rpy="0 0 0"/>
    <mass value="71.5857070563554"/>
    <inertia ixx="0.594464" iyy="0.42119" izz="0.650183" ixy="0.0" iyz="-0.0" ixz="-0.00046"/>
  </inertial>
  <visual>
    <origin xyz="0 0 0" rpy="0 0 0"/>
    <geometry>
      <mesh filename="package://agv_description/meshes/base_link.stl" scale="0.001 0.001 0.001"/>
    </geometry>
    <material name="silver"/>
  </visual>
  <collision>
    <origin xyz="0 0 0" rpy="0 0 0"/>
    <geometry>
      <mesh filename="package://agv_description/meshes/base_link.stl" scale="0.001 0.001 0.001"/>
    </geometry>
  </collision>
</link>

<link name="lidar_1">
  <inertial>
    <origin xyz="0.0 0.0 0.010999999999999954" rpy="0 0 0"/>
    <mass value="0.6646274878118223"/>
    <inertia ixx="0.00023" iyy="0.00023" izz="0.000407" ixy="0.0" iyz="-0.0" ixz="-0.0"/>
  </inertial>
  <visual>
    <origin xyz="-0.05 -0.0 -0.2475" rpy="0 0 0"/>
    <geometry>
      <mesh filename="package://agv_description/meshes/lidar_1.stl" scale="0.001 0.001 0.001"/>
    </geometry>
    <material name="silver"/>
  </visual>
  <collision>
    <origin xyz="-0.05 -0.0 -0.2475" rpy="0 0 0"/>
    <geometry>
      <mesh filename="package://agv_description/meshes/lidar_1.stl" scale="0.001 0.001 0.001"/>
    </geometry>
  </collision>
</link>

<link name="right__1">
  <inertial>
    <origin xyz="-1.264266469291897e-14 0.00949999999999998 -6.938893903907228e-18" rpy="0 0 0"/>
    <mass value="0.48321131129175837"/>
    <inertia ixx="0.000145" iyy="0.000261" izz="0.000145" ixy="-0.0" iyz="-0.0" ixz="-0.0"/>
  </inertial>
  <visual>
    <origin xyz="-0.06 0.1525 -0.0325" rpy="0 0 0"/>
    <geometry>
      <mesh filename="package://agv_description/meshes/right__1.stl" scale="0.001 0.001 0.001"/>
    </geometry>
    <material name="silver"/>
  </visual>
  <collision>
    <origin xyz="-0.06 0.1525 -0.0325" rpy="0 0 0"/>
    <geometry>
      <mesh filename="package://agv_description/meshes/right__1.stl" scale="0.001 0.001 0.001"/>
    </geometry>
  </collision>
</link>

<link name="left_1">
  <inertial>
    <origin xyz="1.2732870313669764e-14 -0.00949999999999998 -6.938893903907228e-18" rpy="0 0 0"/>
    <mass value="0.48321131129175837"/>
    <inertia ixx="0.000145" iyy="0.000261" izz="0.000145" ixy="0.0" iyz="0.0" ixz="0.0"/>
  </inertial>
  <visual>
    <origin xyz="-0.06 -0.1525 -0.0325" rpy="0 0 0"/>
    <geometry>
      <mesh filename="package://agv_description/meshes/left_1.stl" scale="0.001 0.001 0.001"/>
    </geometry>
    <material name="silver"/>
  </visual>
  <collision>
    <origin xyz="-0.06 -0.1525 -0.0325" rpy="0 0 0"/>
    <geometry>
      <mesh filename="package://agv_description/meshes/left_1.stl" scale="0.001 0.001 0.001"/>
    </geometry>
  </collision>
</link>

<joint name="Rigid 1" type="fixed">
  <origin xyz="0.05 0.0 0.2475" rpy="0 0 0"/>
  <parent link="base_link"/>
  <child link="lidar_1"/>
</joint>

<joint name="Revolute 2" type="continuous">
  <origin xyz="0.06 -0.1525 0.0325" rpy="0 0 0"/>
  <parent link="base_link"/>
  <child link="right__1"/>
  <axis xyz="0.0 -1.0 0.0"/>
</joint>

<joint name="Revolute 3" type="continuous">
  <origin xyz="0.06 0.1525 0.0325" rpy="0 0 0"/>
  <parent link="base_link"/>
  <child link="left_1"/>
  <axis xyz="0.0 1.0 0.0"/>
</joint>

</robot>
